Workbook

Sheet Master sheet - do not change
B1: password: tsunami
A3: No | B3: Full name | C3: First name | D3: Last name | E3: Nickname | F3: Gender | G3: Racing | H3: Category | I3: Weight
A4: 1 | B4: Campbell, Mary-Alice | C4: =RIGHT(B4,LEN(B4)-SEARCH(" ",B4)) -> Mary-Alice | D4: =LEFT(B4,LEN(B4)-LEN(C4)-2) -> Campbell | E4: Mary-Alice | F4: F | G4: y | I4: 70
A5: 2 | B5: Constantinou, Lianna | C5: =RIGHT(B5,LEN(B5)-SEARCH(" ",B5)) -> Lianna | D5: =LEFT(B5,LEN(B5)-LEN(C5)-2) -> Constantinou | E5: Lianna C | F5: F | G5: y | I5: 71
A6: 3 | B6: Agudelo, Bibiana | C6: =RIGHT(B6,LEN(B6)-SEARCH(" ",B6)) -> Bibiana | D6: =LEFT(B6,LEN(B6)-LEN(C6)-2) -> Agudelo | E6: Bibiana A | F6: F | G6: y | I6: 75
A7: 4 | B7: Davies, Amanda | C7: =RIGHT(B7,LEN(B7)-SEARCH(" ",B7)) -> Amanda | D7: =LEFT(B7,LEN(B7)-LEN(C7)-2) -> Davies | E7: Amanda D | F7: F | G7: y | I7: 70
A8: 5 | B8: Cheok, Alice | C8: =RIGHT(B8,LEN(B8)-SEARCH(" ",B8)) -> Alice | D8: =LEFT(B8,LEN(B8)-LEN(C8)-2) -> Cheok | E8: Alice C | F8: F | G8: y | I8: 58
A9: 6 | B9: Hu, Yanhua | C9: =RIGHT(B9,LEN(B9)-SEARCH(" ",B9)) -> Yanhua | D9: =LEFT(B9,LEN(B9)-LEN(C9)-2) -> Hu | E9: Amy | F9: F | G9: y | I9: 65
A10: 7 | B10: Finneran, Amanda | C10: =RIGHT(B10,LEN(B10)-SEARCH(" ",B10)) -> Amanda | D10: =LEFT(B10,LEN(B10)-LEN(C10)-2) -> Finneran | E10: Amanda F | F10: F | G10: y | I10: 75
A11: 8 | B11: Ford, Helen | C11: =RIGHT(B11,LEN(B11)-SEARCH(" ",B11)) -> Helen | D11: =LEFT(B11,LEN(B11)-LEN(C11)-2) -> Ford | E11: Helen F | F11: F | G11: y | I11: 55
A12: 9 | B12: Angus, Janet | C12: =RIGHT(B12,LEN(B12)-SEARCH(" ",B12)) -> Janet | D12: =LEFT(B12,LEN(B12)-LEN(C12)-2) -> Angus | E12: Janet A | F12: F | G12: y | I12: 74
A13: 10 | B13: Hasapis, Leah | C13: =RIGHT(B13,LEN(B13)-SEARCH(" ",B13)) -> Leah | D13: =LEFT(B13,LEN(B13)-LEN(C13)-2) -> Hasapis | E13: Leah H | F13: F | G13: y | I13: 73
A14: 11 | B14: Hirst, Deb | C14: =RIGHT(B14,LEN(B14)-SEARCH(" ",B14)) -> Deb | D14: =LEFT(B14,LEN(B14)-LEN(C14)-2) -> Hirst | E14: Deb H | F14: F | G14: y | I14: 64
A15: 12 | B15: Holt, Rachael | C15: =RIGHT(B15,LEN(B15)-SEARCH(" ",B15)) -> Rachael | D15: =LEFT(B15,LEN(B15)-LEN(C15)-2) -> Holt | E15: Rachael H | F15: F | G15: y | I15: 85
... A47: 44 | B47: Hemming, Michael | C47: =RIGHT(B47,LEN(B47)-SEARCH(" ",B47)) -> Michael | D47: =LEFT(B47,LEN(B47)-LEN(C47)-2) -> Hemming | E47: Michael H | F47: M | G47: y | I47: 82
A48: 45 | B48: Van Laeren, Richard | C48: Richard | D48: Van Laeren | E48: Richard V | F48: M | G48: n | I48: 90
A49: 46 | B49: Santos, Marc Ericson | C49: =RIGHT(B49,LEN(B49)-SEARCH(" ",B49)) -> Marc Ericson | D49: =LEFT(B49,LEN(B49)-LEN(C49)-2) -> Santos | E49: Marc | F49: M | G49: n | I49: 71
A50: 47 | B50: Lizarazo, Jaid | C50: =RIGHT(B50,LEN(B50)-SEARCH(" ",B50)) -> Jaid | D50: =LEFT(B50,LEN(B50)-LEN(C50)-2) -> Lizarazo | E50: Jaid | F50: M | G50: n | I50: 68
A51: 48 | B51: Roberts, Matthew | C51: =RIGHT(B51,LEN(B51)-SEARCH(" ",B51)) -> Matthew | D51: =LEFT(B51,LEN(B51)-LEN(C51)-2) -> Roberts | E51: Matthew R | F51: M | G51: n | I51: 5
A52: 49 | B52: Irik, Wendy | C52: =RIGHT(B52,LEN(B52)-SEARCH(" ",B52)) -> Wendy | D52: =LEFT(B52,LEN(B52)-LEN(C52)-2) -> Irik | E52: Wendy I | F52: F | G52: y | I52: 91
A53: 50 | B53: Turnell, Ruth | C53: =RIGHT(B53,LEN(B53)-SEARCH(" ",B53)) -> Ruth | D53: =LEFT(B53,LEN(B53)-LEN(C53)-2) -> Turnell | E53: Ruth T | F53: F | G53: n | I53: 5
A54: 51 | B54: Claro, Anne | C54: =RIGHT(B54,LEN(B54)-SEARCH(" ",B54)) -> Anne | D54: =LEFT(B54,LEN(B54)-LEN(C54)-2) -> Claro | E54: Anne C | F54: F | G54: n | I54: 5

Sheet START HERE
B3: No | C3: Drop your list of names here -> in format -> Valouch, Petr
B4: 1 | C4: Campbell, Mary-Alice
B5: 2 | C5: Davies, Amanda
B6: 3 | C6: Finneran, Amanda
B7: 4 | C7: Ford, Helen
B8: 5 | C8: Hallett, Victoria
B9: 6 | C9: Agudelo, Bibiana
B10: 7 | C10: Hirst, Deb
B11: 8 | C11: Hu, Yanhua
B12: 9 | C12: Kemp, Jocelyn
B13: 10 | C13: Murphy, Alison
B14: 11 | C14: Angus, Janet
B15: 12 | C15: Rennie, Sarah-Jane
... B39: 36 | C39: Moro, Andrea
B40: 37
B41: 38
B42: 39
B43: 40
B44: 41
B45: 42
B46: 43
B47: 44
B48: 45
B49: 46
B50: 47
B51: 48
... B55: 52

Sheet Allocation
F1: Only enter your required allocations here
A2: No | B2: CrewList | C2: Nickname | D2: Weight | E2: Gender | F2: Prem Mix | G2: Master Mix | H2: Prem Open | I2: Prem Women
A3: 1 | B3: =IF(VLOOKUP(A3,'START HERE'!$B$4:$C$55,2)=0,"",VLOOKUP(A3,'START HERE'!$B$4:$C$55,2)) -> Campbell, Mary-Alice | C3: =IF(B3="","",VLOOKUP(B3,'Master sheet - do not change'!$B$3:$I$51,4,)) -> Mary-Alice | D3: =IF(C3="","",VLOOKUP(B3,'Master sheet - do not change'!$B$3:$I$51,8,)) -> 70 | E3: =IF(B3="","",VLOOKUP(B3,'Master sheet - do not change'!$B$3:$I$51,5,)) -> F | H3: 3 | I3: 2
A4: 2 | B4: =IF(VLOOKUP(A4,'START HERE'!$B$4:$C$55,2)=0,"",VLOOKUP(A4,'START HERE'!$B$4:$C$55,2)) -> Davies, Amanda | C4: =IF(B4="","",VLOOKUP(B4,'Master sheet - do not change'!$B$3:$I$51,4,)) -> Amanda D | D4: =IF(C4="","",VLOOKUP(B4,'Master sheet - do not change'!$B$3:$I$51,8,)) -> 70 | E4: =IF(B4="","",VLOOKUP(B4,'Master sheet - do not change'!$B$3:$I$51,5,)) -> F | F4: 3 | H4: 0 | I4: 3
A5: 3 | B5: =IF(VLOOKUP(A5,'START HERE'!$B$4:$C$55,2)=0,"",VLOOKUP(A5,'START HERE'!$B$4:$C$55,2)) -> Finneran, Amanda | C5: =IF(B5="","",VLOOKUP(B5,'Master sheet - do not change'!$B$3:$I$51,4,)) -> Amanda F | D5: =IF(C5="","",VLOOKUP(B5,'Master sheet - do not change'!$B$3:$I$51,8,)) -> 75 | E5: =IF(B5="","",VLOOKUP(B5,'Master sheet - do not change'!$B$3:$I$51,5,)) -> F | H5: 3 | I5: 3
A6: 4 | B6: =IF(VLOOKUP(A6,'START HERE'!$B$4:$C$55,2)=0,"",VLOOKUP(A6,'START HERE'!$B$4:$C$55,2)) -> Ford, Helen | C6: =IF(B6="","",VLOOKUP(B6,'Master sheet - do not change'!$B$3:$I$51,4,)) -> Helen F | D6: =IF(C6="","",VLOOKUP(B6,'Master sheet - do not change'!$B$3:$I$51,8,)) -> 55 | E6: =IF(B6="","",VLOOKUP(B6,'Master sheet - do not change'!$B$3:$I$51,5,)) -> F | F6: Drum | I6: 3
A7: 5 | B7: =IF(VLOOKUP(A7,'START HERE'!$B$4:$C$55,2)=0,"",VLOOKUP(A7,'START HERE'!$B$4:$C$55,2)) -> Hallett, Victoria | C7: =IF(B7="","",VLOOKUP(B7,'Master sheet - do not change'!$B$3:$I$51,4,)) -> Victoria H | D7: =IF(C7="","",VLOOKUP(B7,'Master sheet - do not change'!$B$3:$I$51,8,)) -> 58 | E7: =IF(B7="","",VLOOKUP(B7,'Master sheet - do not change'!$B$3:$I$51,5,)) -> F | F7: 3 | I7: 3
A8: 6 | B8: =IF(VLOOKUP(A8,'START HERE'!$B$4:$C$55,2)=0,"",VLOOKUP(A8,'START HERE'!$B$4:$C$55,2)) -> Agudelo, Bibiana | C8: =IF(B8="","",VLOOKUP(B8,'Master sheet - do not change'!$B$3:$I$51,4,)) -> Bibiana A | D8: =IF(C8="","",VLOOKUP(B8,'Master sheet - do not change'!$B$3:$I$51,8,)) -> 75 | E8: =IF(B8="","",VLOOKUP(B8,'Master sheet - do not change'!$B$3:$I$51,5,)) -> F | H8: 3 | I8: 3
A9: 7 | B9: =IF(VLOOKUP(A9,'START HERE'!$B$4:$C$55,2)=0,"",VLOOKUP(A9,'START HERE'!$B$4:$C$55,2)) -> Hirst, Deb | C9: =IF(B9="","",VLOOKUP(B9,'Master sheet - do not change'!$B$3:$I$51,4,)) -> Deb H | D9: =IF(C9="","",VLOOKUP(B9,'Master sheet - do not change'!$B$3:$I$51,8,)) -> 64 | E9: =IF(B9="","",VLOOKUP(B9,'Master sheet - do not change'!$B$3:$I$51,5,)) -> F | F9: 3 | H9: 0 | I9: 3
A10: 8 | B10: =IF(VLOOKUP(A10,'START HERE'!$B$4:$C$55,2)=0,"",VLOOKUP(A10,'START HERE'!$B$4:$C$55,2)) -> Hu, Yanhua | C10: =IF(B10="","",VLOOKUP(B10,'Master sheet - do not change'!$B$3:$I$51,4,)) -> Amy | D10: =IF(C10="","",VLOOKUP(B10,'Master sheet - do not change'!$B$3:$I$51,8,)) -> 65 | E10: =IF(B10="","",VLOOKUP(B10,'Master sheet - do not change'!$B$3:$I$51,5,)) -> F | H10: 3 | I10: 3
A11: 9 | B11: =IF(VLOOKUP(A11,'START HERE'!$B$4:$C$55,2)=0,"",VLOOKUP(A11,'START HERE'!$B$4:$C$55,2)) -> Kemp, Jocelyn | C11: =IF(B11="","",VLOOKUP(B11,'Master sheet - do not change'!$B$3:$I$51,4,)) -> Jocelyn K | D11: =IF(C11="","",VLOOKUP(B11,'Master sheet - do not change'!$B$3:$I$51,8,)) -> 58 | E11: =IF(B11="","",VLOOKUP(B11,'Master sheet - do not change'!$B$3:$I$51,5,)) -> F | F11: 3 | H11: 0 | I11: 3
A12: 10 | B12: =IF(VLOOKUP(A12,'START HERE'!$B$4:$C$55,2)=0,"",VLOOKUP(A12,'START HERE'!$B$4:$C$55,2)) -> Murphy, Alison | C12: =IF(B12="","",VLOOKUP(B12,'Master sheet - do not change'!$B$3:$I$51,4,)) -> Alison M | D12: =IF(C12="","",VLOOKUP(B12,'Master sheet - do not change'!$B$3:$I$51,8,)) -> 74 | E12: =IF(B12="","",VLOOKUP(B12,'Master sheet - do not change'!$B$3:$I$51,5,)) -> F | F12: 3 | I12: 3
A13: 11 | B13: =IF(VLOOKUP(A13,'START HERE'!$B$4:$C$55,2)=0,"",VLOOKUP(A13,'START HERE'!$B$4:$C$55,2)) -> Angus, Janet | C13: =IF(B13="","",VLOOKUP(B13,'Master sheet - do not change'!$B$3:$I$51,4,)) -> Janet A | D13: =IF(C13="","",VLOOKUP(B13,'Master sheet - do not change'!$B$3:$I$51,8,)) -> 74 | E13: =IF(B13="","",VLOOKUP(B13,'Master sheet - do not change'!$B$3:$I$51,5,)) -> F | F13: 2 | I13: 2
A14: 12 | B14: =IF(VLOOKUP(A14,'START HERE'!$B$4:$C$55,2)=0,"",VLOOKUP(A14,'START HERE'!$B$4:$C$55,2)) -> Rennie, Sarah-Jane | C14: =IF(B14="","",VLOOKUP(B14,'Master sheet - do not change'!$B$3:$I$51,4,)) -> S-J | D14: =IF(C14="","",VLOOKUP(B14,'Master sheet - do not change'!$B$3:$I$51,8,)) -> 62 | E14: =IF(B14="","",VLOOKUP(B14,'Master sheet - do not change'!$B$3:$I$51,5,)) -> F | F14: Sweep | H14: 0 | I14: Sweep
A15: 13 | B15: =IF(VLOOKUP(A15,'START HERE'!$B$4:$C$55,2)=0,"",VLOOKUP(A15,'START HERE'!$B$4:$C$55,2)) -> Tolhurst, Sue | C15: =IF(B15="","",VLOOKUP(B15,'Master sheet - do not change'!$B$3:$I$51,4,)) -> Sue T | D15: =IF(C15="","",VLOOKUP(B15,'Master sheet - do not change'!$B$3:$I$51,8,)) -> 63 | E15: =IF(B15="","",VLOOKUP(B15,'Master sheet - do not change'!$B$3:$I$51,5,)) -> F | H15: Drum | I15: 3
A16: 14 | B16: =IF(VLOOKUP(A16,'START HERE'!$B$4:$C$55,2)=0,"",VLOOKUP(A16,'START HERE'!$B$4:$C$55,2)) -> Bauzon, Ma Divina Angela | C16: =IF(B16="","",VLOOKUP(B16,'Master sheet - do not change'!$B$3:$I$51,4,)) -> Divina | D16: =IF(C16="","",VLOOKUP(B16,'Master sheet - do not change'!$B$3:$I$51,8,)) -> 54 | E16: =IF(B16="","",VLOOKUP(B16,'Master sheet - do not change'!$B$3:$I$51,5,)) -> F | F16: 2 | I16: 3
A17: 15 | B17: =IF(VLOOKUP(A17,'START HERE'!$B$4:$C$55,2)=0,"",VLOOKUP(A17,'START HERE'!$B$4:$C$55,2)) -> Cheok, Alice | C17: =IF(B17="","",VLOOKUP(B17,'Master sheet - do not change'!$B$3:$I$51,4,)) -> Alice C | D17: =IF(C17="","",VLOOKUP(B17,'Master sheet - do not change'!$B$3:$I$51,8,)) -> 58 | E17: =IF(B17="","",VLOOKUP(B17,'Master sheet - do not change'!$B$3:$I$51,5,)) -> F | F17: 2 | I17: 3
A18: 16 | B18: =IF(VLOOKUP(A18,'START HERE'!$B$4:$C$55,2)=0,"",VLOOKUP(A18,'START HERE'!$B$4:$C$55,2)) -> Chiu, Miu | C18: =IF(B18="","",VLOOKUP(B18,'Master sheet - do not change'!$B$3:$I$51,4,)) -> Miu | D18: =IF(C18="","",VLOOKUP(B18,'Master sheet - do not change'!$B$3:$I$51,8,)) -> 52 | E18: =IF(B18="","",VLOOKUP(B18,'Master sheet - do not change'!$B$3:$I$51,5,)) -> F | F18: 3 | I18: 3
A19: 17 | B19: =IF(VLOOKUP(A19,'START HERE'!$B$4:$C$55,2)=0,"",VLOOKUP(A19,'START HERE'!$B$4:$C$55,2)) -> Dobner, Anne-Marie | C19: =IF(B19="","",VLOOKUP(B19,'Master sheet - do not change'!$B$3:$I$51,4,)) -> Anne-Marie | D19: =IF(C19="","",VLOOKUP(B19,'Master sheet - do not change'!$B$3:$I$51,8,)) -> 67 | E19: =IF(B19="","",VLOOKUP(B19,'Master sheet - do not change'!$B$3:$I$51,5,)) -> F | H19: 3 | I19: 3
A20: 18 | B20: =IF(VLOOKUP(A20,'START HERE'!$B$4:$C$55,2)=0,"",VLOOKUP(A20,'START HERE'!$B$4:$C$55,2)) -> Hasapis, Leah | C20: =IF(B20="","",VLOOKUP(B20,'Master sheet - do not change'!$B$3:$I$51,4,)) -> Leah H | D20: =IF(C20="","",VLOOKUP(B20,'Master sheet - do not change'!$B$3:$I$51,8,)) -> 73 | E20: =IF(B20="","",VLOOKUP(B20,'Master sheet - do not change'!$B$3:$I$51,5,)) -> F | F20: 2 | I20: 3
A21: 19 | B21: =IF(VLOOKUP(A21,'START HERE'!$B$4:$C$55,2)=0,"",VLOOKUP(A21,'START HERE'!$B$4:$C$55,2)) -> Holt, Rachael | C21: =IF(B21="","",VLOOKUP(B21,'Master sheet - do not change'!$B$3:$I$51,4,)) -> Rachael H | D21: =IF(C21="","",VLOOKUP(B21,'Master sheet - do not change'!$B$3:$I$51,8,)) -> 85 | E21: =IF(B21="","",VLOOKUP(B21,'Master sheet - do not change'!$B$3:$I$51,5,)) -> F | H21: 3 | I21: 2
A22: 20 | B22: =IF(VLOOKUP(A22,'START HERE'!$B$4:$C$55,2)=0,"",VLOOKUP(A22,'START HERE'!$B$4:$C$55,2)) -> McKenna, Elizabeth | C22: =IF(B22="","",VLOOKUP(B22,'Master sheet - do not change'!$B$3:$I$51,4,)) -> Liz Mc | D22: =IF(C22="","",VLOOKUP(B22,'Master sheet - do not change'!$B$3:$I$51,8,)) -> 64 | E22: =IF(B22="","",VLOOKUP(B22,'Master sheet - do not change'!$B$3:$I$51,5,)) -> F | H22: 3 | I22: 3
A23: 21 | B23: =IF(VLOOKUP(A23,'START HERE'!$B$4:$C$55,2)=0,"",VLOOKUP(A23,'START HERE'!$B$4:$C$55,2)) -> Rai, Rohini | C23: =IF(B23="","",VLOOKUP(B23,'Master sheet - do not change'!$B$3:$I$51,4,)) -> Rohini | D23: =IF(C23="","",VLOOKUP(B23,'Master sheet - do not change'!$B$3:$I$51,8,)) -> 70 | E23: =IF(B23="","",VLOOKUP(B23,'Master sheet - do not change'!$B$3:$I$51,5,)) -> F | F23: 3 | I23: 3
A24: 22 | B24: =IF(VLOOKUP(A24,'START HERE'!$B$4:$C$55,2)=0,"",VLOOKUP(A24,'START HERE'!$B$4:$C$55,2)) -> Steel, Alice | C24: =IF(B24="","",VLOOKUP(B24,'Master sheet - do not change'!$B$3:$I$51,4,)) -> Alice S | D24: =IF(C24="","",VLOOKUP(B24,'Master sheet - do not change'!$B$3:$I$51,8,)) -> 47 | E24: =IF(B24="","",VLOOKUP(B24,'Master sheet - do not change'!$B$3:$I$51,5,)) -> F | H24: 3 | I24: Drum
A25: 23 | B25: =IF(VLOOKUP(A25,'START HERE'!$B$4:$C$55,2)=0,"",VLOOKUP(A25,'START HERE'!$B$4:$C$55,2)) -> Constantinou, Lianna | C25: =IF(B25="","",VLOOKUP(B25,'Master sheet - do not change'!$B$3:$I$51,4,)) -> Lianna C | D25: =IF(C25="","",VLOOKUP(B25,'Master sheet - do not change'!$B$3:$I$51,8,)) -> 71 | E25: =IF(B25="","",VLOOKUP(B25,'Master sheet - do not change'!$B$3:$I$51,5,)) -> F | F25: 3 | I25: 3
A26: 24 | B26: =IF(VLOOKUP(A26,'START HERE'!$B$4:$C$55,2)=0,"",VLOOKUP(A26,'START HERE'!$B$4:$C$55,2)) -> Hemming, Michael | C26: =IF(B26="","",VLOOKUP(B26,'Master sheet - do not change'!$B$3:$I$51,4,)) -> Michael H | D26: =IF(C26="","",VLOOKUP(B26,'Master sheet - do not change'!$B$3:$I$51,8,)) -> 82 | E26: =IF(B26="","",VLOOKUP(B26,'Master sheet - do not change'!$B$3:$I$51,5,)) -> M | F26: 2 | H26: 3
A27: 25 | B27: =IF(VLOOKUP(A27,'START HERE'!$B$4:$C$55,2)=0,"",VLOOKUP(A27,'START HERE'!$B$4:$C$55,2)) -> Boerma, Andrew | C27: =IF(B27="","",VLOOKUP(B27,'Master sheet - do not change'!$B$3:$I$51,4,)) -> Andrew B | D27: =IF(C27="","",VLOOKUP(B27,'Master sheet - do not change'!$B$3:$I$51,8,)) -> 75 | E27: =IF(B27="","",VLOOKUP(B27,'Master sheet - do not change'!$B$3:$I$51,5,)) -> M | F27: 3 | H27: 3
A28: 26 | B28: =IF(VLOOKUP(A28,'START HERE'!$B$4:$C$55,2)=0,"",VLOOKUP(A28,'START HERE'!$B$4:$C$55,2)) -> Escalona, Diego | C28: =IF(B28="","",VLOOKUP(B28,'Master sheet - do not change'!$B$3:$I$51,4,)) -> Diego E | D28: =IF(C28="","",VLOOKUP(B28,'Master sheet - do not change'!$B$3:$I$51,8,)) -> 84 | E28: =IF(B28="","",VLOOKUP(B28,'Master sheet - do not change'!$B$3:$I$51,5,)) -> M | F28: 3 | H28: 3
A29: 27 | B29: =IF(VLOOKUP(A29,'START HERE'!$B$4:$C$55,2)=0,"",VLOOKUP(A29,'START HERE'!$B$4:$C$55,2)) -> Freke, Simon | C29: =IF(B29="","",VLOOKUP(B29,'Master sheet - do not change'!$B$3:$I$51,4,)) -> Simon F | D29: =IF(C29="","",VLOOKUP(B29,'Master sheet - do not change'!$B$3:$I$51,8,)) -> 64 | E29: =IF(B29="","",VLOOKUP(B29,'Master sheet - do not change'!$B$3:$I$51,5,)) -> M | F29: 2 | H29: 3
A30: 28 | B30: =IF(VLOOKUP(A30,'START HERE'!$B$4:$C$55,2)=0,"",VLOOKUP(A30,'START HERE'!$B$4:$C$55,2)) -> Harris, Andrew | C30: =IF(B30="","",VLOOKUP(B30,'Master sheet - do not change'!$B$3:$I$51,4,)) -> Andrew H | D30: =IF(C30="","",VLOOKUP(B30,'Master sheet - do not change'!$B$3:$I$51,8,)) -> 77 | E30: =IF(B30="","",VLOOKUP(B30,'Master sheet - do not change'!$B$3:$I$51,5,)) -> M | F30: 2 | H30: 3
A31: 29 | B31: =IF(VLOOKUP(A31,'START HERE'!$B$4:$C$55,2)=0,"",VLOOKUP(A31,'START HERE'!$B$4:$C$55,2)) -> Haupt, Detlef | C31: =IF(B31="","",VLOOKUP(B31,'Master sheet - do not change'!$B$3:$I$51,4,)) -> Detlef H | D31: =IF(C31="","",VLOOKUP(B31,'Master sheet - do not change'!$B$3:$I$51,8,)) -> 90 | E31: =IF(B31="","",VLOOKUP(B31,'Master sheet - do not change'!$B$3:$I$51,5,)) -> M | F31: 2 | H31: 3
A32: 30 | B32: =IF(VLOOKUP(A32,'START HERE'!$B$4:$C$55,2)=0,"",VLOOKUP(A32,'START HERE'!$B$4:$C$55,2)) -> Jeffree, Paul | C32: =IF(B32="","",VLOOKUP(B32,'Master sheet - do not change'!$B$3:$I$51,4,)) -> Paul J | D32: =IF(C32="","",VLOOKUP(B32,'Master sheet - do not change'!$B$3:$I$51,8,)) -> 91 | E32: =IF(B32="","",VLOOKUP(B32,'Master sheet - do not change'!$B$3:$I$51,5,)) -> M | F32: 3 | H32: 3
A33: 31 | B33: =IF(VLOOKUP(A33,'START HERE'!$B$4:$C$55,2)=0,"",VLOOKUP(A33,'START HERE'!$B$4:$C$55,2)) -> Lizarazo, Jaid | C33: =IF(B33="","",VLOOKUP(B33,'Master sheet - do not change'!$B$3:$I$51,4,)) -> Jaid | D33: =IF(C33="","",VLOOKUP(B33,'Master sheet - do not change'!$B$3:$I$51,8,)) -> 68 | E33: =IF(B33="","",VLOOKUP(B33,'Master sheet - do not change'!$B$3:$I$51,5,)) -> M | F33: 3 | H33: 3
A34: 32 | B34: =IF(VLOOKUP(A34,'START HERE'!$B$4:$C$55,2)=0,"",VLOOKUP(A34,'START HERE'!$B$4:$C$55,2)) -> Ramrakha, Kiran | C34: =IF(B34="","",VLOOKUP(B34,'Master sheet - do not change'!$B$3:$I$51,4,)) -> Kiran R | D34: =IF(C34="","",VLOOKUP(B34,'Master sheet - do not change'!$B$3:$I$51,8,)) -> 95 | E34: =IF(B34="","",VLOOKUP(B34,'Master sheet - do not change'!$B$3:$I$51,5,)) -> M | F34: 2 | H34: 3
A35: 33 | B35: =IF(VLOOKUP(A35,'START HERE'!$B$4:$C$55,2)=0,"",VLOOKUP(A35,'START HERE'!$B$4:$C$55,2)) -> Santos, marc Ericson | C35: =IF(B35="","",VLOOKUP(B35,'Master sheet - do not change'!$B$3:$I$51,4,)) -> Marc | D35: =IF(C35="","",VLOOKUP(B35,'Master sheet - do not change'!$B$3:$I$51,8,)) -> 71 | E35: =IF(B35="","",VLOOKUP(B35,'Master sheet - do not change'!$B$3:$I$51,5,)) -> M | F35: 3 | H35: 3
A36: 34 | B36: =IF(VLOOKUP(A36,'START HERE'!$B$4:$C$55,2)=0,"",VLOOKUP(A36,'START HERE'!$B$4:$C$55,2)) -> Valouch, Petr | C36: =IF(B36="","",VLOOKUP(B36,'Master sheet - do not change'!$B$3:$I$51,4,)) -> Petr V | D36: =IF(C36="","",VLOOKUP(B36,'Master sheet - do not change'!$B$3:$I$51,8,)) -> 73 | E36: =IF(B36="","",VLOOKUP(B36,'Master sheet - do not change'!$B$3:$I$51,5,)) -> M | H36: Sweep
A37: 35 | B37: =IF(VLOOKUP(A37,'START HERE'!$B$4:$C$55,2)=0,"",VLOOKUP(A37,'START HERE'!$B$4:$C$55,2)) -> Van Laeren, Richard | C37: =IF(B37="","",VLOOKUP(B37,'Master sheet - do not change'!$B$3:$I$51,4,)) -> Richard V | D37: =IF(C37="","",VLOOKUP(B37,'Master sheet - do not change'!$B$3:$I$51,8,)) -> 90 | E37: =IF(B37="","",VLOOKUP(B37,'Master sheet - do not change'!$B$3:$I$51,5,)) -> M | F37: 2 | H37: 3
A38: 36 | B38: =IF(VLOOKUP(A38,'START HERE'!$B$4:$C$55,2)=0,"",VLOOKUP(A38,'START HERE'!$B$4:$C$55,2)) -> Moro, Andrea | C38: =IF(B38="","",VLOOKUP(B38,'Master sheet - do not change'!$B$3:$I$51,4,)) -> Andrea M | D38: =IF(C38="","",VLOOKUP(B38,'Master sheet - do not change'!$B$3:$I$51,8,)) -> 65 | E38: =IF(B38="","",VLOOKUP(B38,'Master sheet - do not change'!$B$3:$I$51,5,)) -> M | F38: 3 | H38: 3
A39: 37 | B39: =IF(VLOOKUP(A39,'START HERE'!$B$4:$C$55,2)=0,"",VLOOKUP(A39,'START HERE'!$B$4:$C$55,2)) | C39: =IF(B39="","",VLOOKUP(B39,'Master sheet - do not change'!$B$3:$I$51,4,)) | D39: =IF(C39="","",VLOOKUP(B39,'Master sheet - do not change'!$B$3:$I$51,8,)) | E39: =IF(B39="","",VLOOKUP(B39,'Master sheet - do not change'!$B$3:$I$51,5,))
A40: 38 | B40: =IF(VLOOKUP(A40,'START HERE'!$B$4:$C$55,2)=0,"",VLOOKUP(A40,'START HERE'!$B$4:$C$55,2)) | C40: =IF(B40="","",VLOOKUP(B40,'Master sheet - do not change'!$B$3:$I$51,4,)) | D40: =IF(C40="","",VLOOKUP(B40,'Master sheet - do not change'!$B$3:$I$51,8,)) | E40: =IF(B40="","",VLOOKUP(B40,'Master sheet - do not change'!$B$3:$I$51,5,))
...

Sheet Prem Mix
G2: Enter names into the blue zones only - match the names from the "Name" column
A3: No | B3: Name | C3: Weight | D3: Prem Mix
A4: 1 | B4: =IF(Allocation!F3="","",VLOOKUP(A4,Allocation!$A$2:$I$47,3)) | C4: =IF(B4="","",VLOOKUP(A4,Allocation!$A$2:$I$47,4,)) | D4: =IF(B4="","",VLOOKUP(A4,Allocation!$A$2:$I$47,6,)) | F4: Heat 1
A5: 2 | B5: =IF(Allocation!F4="","",VLOOKUP(A5,Allocation!$A$2:$I$47,3)) -> Amanda D | C5: =IF(B5="","",VLOOKUP(A5,Allocation!$A$2:$I$47,4,)) -> 70 | D5: =IF(B5="","",VLOOKUP(A5,Allocation!$A$2:$I$47,6,)) -> 3 | G5: Helen F | H5: =IF(G5="","",VLOOKUP(G5,$B$4:$C$48,2,)) -> 55 | L5: Kg's | M5: Left | N5: Right | O5: Kg's | T5: =H5+14 -> 69 | U5: 6 | V5: =(U5)/6 -> 1 | W5: =V5*T5 -> 69
A6: 3 | B6: =IF(Allocation!F5="","",VLOOKUP(A6,Allocation!$A$2:$I$47,3)) | C6: =IF(B6="","",VLOOKUP(A6,Allocation!$A$2:$I$47,4,)) | D6: =IF(B6="","",VLOOKUP(A6,Allocation!$A$2:$I$47,6,)) | F6: =IF(G6="","",VLOOKUP(G6,$B$4:$C$48,2,)) -> 71 | G6: Lianna C | H6: Diego E | I6: =IF(H6="","",VLOOKUP(H6,$B$4:$C$48,2,)) -> 84 | K6: 1 | L6: =F6 -> 71 | M6: =G6 -> Lianna C | N6: =H6 -> Diego E | O6: =I6 -> 84 | P6: =O6-L6 -> 13 | Q6: 300 | R6: =Q6/350 -> 0.85714286 | S6: =P6*R6 -> 11.142857 | T6: =L6+O6 -> 155 | U6: 4.5 | V6: =(U6)/6 -> 0.75 | W6: =V6*T6 -> 116.25
A7: 4 | B7: =IF(Allocation!F6="","",VLOOKUP(A7,Allocation!$A$2:$I$47,3)) -> Helen F | C7: =IF(B7="","",VLOOKUP(A7,Allocation!$A$2:$I$47,4,)) -> 55 | D7: =IF(B7="","",VLOOKUP(A7,Allocation!$A$2:$I$47,6,)) -> Drum | F7: =IF(G7="","",VLOOKUP(G7,$B$4:$C$48,2,)) -> 64 | G7: Deb H | H7: Amanda D | I7: =IF(H7="","",VLOOKUP(H7,$B$4:$C$48,2,)) -> 70 | K7: 2 | L7: =F7 -> 64 | M7: =G7 -> Deb H | N7: =H7 -> Amanda D | O7: =I7 -> 70 | P7: =O7-L7 -> 6 | Q7: 330 | R7: =Q7/350 -> 0.94285714 | S7: =P7*R7 -> 5.6571429 | T7: =L7+O7 -> 134 | U7: 3.5 | V7: =(U7)/6 -> 0.58333333 | W7: =V7*T7 -> 78.166667
A8: 5 | B8: =IF(Allocation!F7="","",VLOOKUP(A8,Allocation!$A$2:$I$47,3)) -> Victoria H | C8: =IF(B8="","",VLOOKUP(A8,Allocation!$A$2:$I$47,4,)) -> 58 | D8: =IF(B8="","",VLOOKUP(A8,Allocation!$A$2:$I$47,6,)) -> 3 | F8: =IF(G8="","",VLOOKUP(G8,$B$4:$C$48,2,)) -> 65 | G8: Andrea M | H8: Victoria H | I8: =IF(H8="","",VLOOKUP(H8,$B$4:$C$48,2,)) -> 58 | K8: 3 | L8: =F8 -> 65 | M8: =G8 -> Andrea M | N8: =H8 -> Victoria H | O8: =I8 -> 58 | P8: =O8-L8 -> -7 | Q8: 350 | R8: =Q8/350 -> 1 | S8: =P8*R8 -> -7 | T8: =L8+O8 -> 123 | U8: 2.5 | V8: =(U8)/6 -> 0.41666667 | W8: =V8*T8 -> 51.25
A9: 6 | B9: =IF(Allocation!F8="","",VLOOKUP(A9,Allocation!$A$2:$I$47,3)) | C9: =IF(B9="","",VLOOKUP(A9,Allocation!$A$2:$I$47,4,)) | D9: =IF(B9="","",VLOOKUP(A9,Allocation!$A$2:$I$47,6,)) | F9: =IF(G9="","",VLOOKUP(G9,$B$4:$C$48,2,)) -> 75 | G9: Andrew B | H9: Paul J | I9: =IF(H9="","",VLOOKUP(H9,$B$4:$C$48,2,)) -> 91 | K9: 4 | L9: =F9 -> 75 | M9: =G9 -> Andrew B | N9: =H9 -> Paul J | O9: =I9 -> 91 | P9: =O9-L9 -> 16 | Q9: 350 | R9: =Q9/350 -> 1 | S9: =P9*R9 -> 16 | T9: =L9+O9 -> 166 | U9: 1.5 | V9: =(U9)/6 -> 0.25 | W9: =V9*T9 -> 41.5
A10: 7 | B10: =IF(Allocation!F9="","",VLOOKUP(A10,Allocation!$A$2:$I$47,3)) -> Deb H | C10: =IF(B10="","",VLOOKUP(A10,Allocation!$A$2:$I$47,4,)) -> 64 | D10: =IF(B10="","",VLOOKUP(A10,Allocation!$A$2:$I$47,6,)) -> 3 | F10: =IF(G10="","",VLOOKUP(G10,$B$4:$C$48,2,)) -> 74 | G10: Alison M | H10: Miu | I10: =IF(H10="","",VLOOKUP(H10,$B$4:$C$48,2,)) -> 52 | K10: 5 | L10: =F10 -> 74 | M10: =G10 -> Alison M | N10: =H10 -> Miu | O10: =I10 -> 52 | P10: =O10-L10 -> -22 | Q10: 350 | R10: =Q10/350 -> 1 | S10: =P10*R10 -> -22 | T10: =L10+O10 -> 126 | U10: 0.5 | V10: =(U10)/6 -> 0.083333333 | W10: =V10*T10 -> 10.5
A11: 8 | B11: =IF(Allocation!F10="","",VLOOKUP(A11,Allocation!$A$2:$I$47,3)) | C11: =IF(B11="","",VLOOKUP(A11,Allocation!$A$2:$I$47,4,)) | D11: =IF(B11="","",VLOOKUP(A11,Allocation!$A$2:$I$47,6,)) | F11: =IF(G11="","",VLOOKUP(G11,$B$4:$C$48,2,)) -> 73 | G11: Leah H | H11: Andrew H | I11: =IF(H11="","",VLOOKUP(H11,$B$4:$C$48,2,)) -> 77 | K11: 6 | L11: =F11 -> 73 | M11: =G11 -> Leah H | N11: =H11 -> Andrew H | O11: =I11 -> 77 | P11: =O11-L11 -> 4 | Q11: 350 | R11: =Q11/350 -> 1 | S11: =P11*R11 -> 4 | T11: =L11+O11 -> 150 | U11: -0.5 | V11: =(U11)/6 -> -0.083333333 | W11: =V11*T11 -> -12.5
A12: 9 | B12: =IF(Allocation!F11="","",VLOOKUP(A12,Allocation!$A$2:$I$47,3)) -> Jocelyn K | C12: =IF(B12="","",VLOOKUP(A12,Allocation!$A$2:$I$47,4,)) -> 58 | D12: =IF(B12="","",VLOOKUP(A12,Allocation!$A$2:$I$47,6,)) -> 3 | F12: =IF(G12="","",VLOOKUP(G12,$B$4:$C$48,2,)) -> 58 | G12: Jocelyn K | H12: Jaid | I12: =IF(H12="","",VLOOKUP(H12,$B$4:$C$48,2,)) -> 68 | K12: 7 | L12: =F12 -> 58 | M12: =G12 -> Jocelyn K | N12: =H12 -> Jaid | O12: =I12 -> 68 | P12: =O12-L12 -> 10 | Q12: 350 | R12: =Q12/350 -> 1 | S12: =P12*R12 -> 10 | T12: =L12+O12 -> 126 | U12: -1.5 | V12: =(U12)/6 -> -0.25 | W12: =V12*T12 -> -31.5
A13: 10 | B13: =IF(Allocation!F12="","",VLOOKUP(A13,Allocation!$A$2:$I$47,3)) -> Alison M | C13: =IF(B13="","",VLOOKUP(A13,Allocation!$A$2:$I$47,4,)) -> 74 | D13: =IF(B13="","",VLOOKUP(A13,Allocation!$A$2:$I$47,6,)) -> 3 | F13: =IF(G13="","",VLOOKUP(G13,$B$4:$C$48,2,)) -> 71 | G13: Marc | H13: Detlef H | I13: =IF(H13="","",VLOOKUP(H13,$B$4:$C$48,2,)) -> 90 | K13: 8 | L13: =F13 -> 71 | M13: =G13 -> Marc | N13: =H13 -> Detlef H | O13: =I13 -> 90 | P13: =O13-L13 -> 19 | Q13: 350 | R13: =Q13/350 -> 1 | S13: =P13*R13 -> 19 | T13: =L13+O13 -> 161 | U13: -2.5 | V13: =(U13)/6 -> -0.41666667 | W13: =V13*T13 -> -67.083333
A14: 11 | B14: =IF(Allocation!F13="","",VLOOKUP(A14,Allocation!$A$2:$I$47,3)) -> Janet A | C14: =IF(B14="","",VLOOKUP(A14,Allocation!$A$2:$I$47,4,)) -> 74 | D14: =IF(B14="","",VLOOKUP(A14,Allocation!$A$2:$I$47,6,)) -> 2 | F14: =IF(G14="","",VLOOKUP(G14,$B$4:$C$48,2,)) -> 90 | G14: Richard V | H14: Alice C | I14: =IF(H14="","",VLOOKUP(H14,$B$4:$C$48,2,)) -> 58 | K14: 9 | L14: =F14 -> 90 | M14: =G14 -> Richard V | N14: =H14 -> Alice C | O14: =I14 -> 58 | P14: =O14-L14 -> -32 | Q14: 330 | R14: =Q14/350 -> 0.94285714 | S14: =P14*R14 -> -30.171429 | T14: =L14+O14 -> 148 | U14: -3.5 | V14: =(U14)/6 -> -0.58333333 | W14: =V14*T14 -> -86.333333
A15: 12 | B15: =IF(Allocation!F14="","",VLOOKUP(A15,Allocation!$A$2:$I$47,3)) -> S-J | C15: =IF(B15="","",VLOOKUP(A15,Allocation!$A$2:$I$47,4,)) -> 62 | D15: =IF(B15="","",VLOOKUP(A15,Allocation!$A$2:$I$47,6,)) -> Sweep | F15: =IF(G15="","",VLOOKUP(G15,$B$4:$C$48,2,)) -> 64 | G15: Simon F | H15: Divina | I15: =IF(H15="","",VLOOKUP(H15,$B$4:$C$48,2,)) -> 54 | K15: 10 | L15: =F15 -> 64 | M15: =G15 -> Simon F | N15: =H15 -> Divina | O15: =I15 -> 54 | P15: =O15-L15 -> -10 | Q15: 300 | R15: =Q15/350 -> 0.85714286 | S15: =P15*R15 -> -8.5714286 | T15: =L15+O15 -> 118 | U15: -4.5 | V15: =(U15)/6 -> -0.75 | W15: =V15*T15 -> -88.5
A16: 13 | B16: =IF(Allocation!F15="","",VLOOKUP(A16,Allocation!$A$2:$I$47,3)) | C16: =IF(B16="","",VLOOKUP(A16,Allocation!$A$2:$I$47,4,)) | D16: =IF(B16="","",VLOOKUP(A16,Allocation!$A$2:$I$47,6,)) | G16: S-J | H16: =IF(G16="","",VLOOKUP(G16,$B$4:$C$48,2,)) -> 62 | L16: 3 | P16: =O16-L16 -> -3 | Q16: 420 | R16: =Q16/350 -> 1.2 | S16: =P16*R16 -> -3.6 | T16: =H16+7 -> 69 | U16: -6 | V16: =(U16)/6 -> -1 | W16: =V16*T16 -> -69
A17: 14 | B17: =IF(Allocation!F16="","",VLOOKUP(A17,Allocation!$A$2:$I$47,3)) -> Divina | C17: =IF(B17="","",VLOOKUP(A17,Allocation!$A$2:$I$47,4,)) -> 54 | D17: =IF(B17="","",VLOOKUP(A17,Allocation!$A$2:$I$47,6,)) -> 2 | L17: =SUM(L6:L16) -> 708 | O17: =SUM(O6:O16) -> 702 | S17: =SUM(S6:S16) -> -5.5428571 | W17: =SUM(W5:W16) -> 11.75
A18: 15 | B18: =IF(Allocation!F17="","",VLOOKUP(A18,Allocation!$A$2:$I$47,3)) -> Alice C | C18: =IF(B18="","",VLOOKUP(A18,Allocation!$A$2:$I$47,4,)) -> 58 | D18: =IF(B18="","",VLOOKUP(A18,Allocation!$A$2:$I$47,6,)) -> 2 | F18: Reserves: | L18: Res. | O18: 87 | S18: left-right | W18: back-front
A19: 16 | B19: =IF(Allocation!F18="","",VLOOKUP(A19,Allocation!$A$2:$I$47,3)) -> Miu | C19: =IF(B19="","",VLOOKUP(A19,Allocation!$A$2:$I$47,4,)) -> 52 | D19: =IF(B19="","",VLOOKUP(A19,Allocation!$A$2:$I$47,6,)) -> 3 | G19: Rohini | H19: =IF(G19="","",VLOOKUP(G19,$B$4:$C$48,2,)) -> 70 | L19: =H19 -> 70 | M19: =G19 -> Rohini | N19: Total Paddlers Weight | Q19: =SUM(O6:O15,L6:L15) -> 1407 | S19: balance | W19: balance
A20: 17 | B20: =IF(Allocation!F19="","",VLOOKUP(A20,Allocation!$A$2:$I$47,3)) | C20: =IF(B20="","",VLOOKUP(A20,Allocation!$A$2:$I$47,4,)) | D20: =IF(B20="","",VLOOKUP(A20,Allocation!$A$2:$I$47,6,)) | G20: Janet A | H20: =IF(G20="","",VLOOKUP(G20,$B$4:$C$48,2,)) -> 74 | L20: =H20 -> 74 | M20: =G20 -> Janet A | N20: Average Paddler Weight | Q20: =SUM(O6:O15,L6:L15)/20 -> 70.35 | S20: Aim for weight under 5 kg | W20: Aim for range of - 15 kg to -25 kg
A21: 18 | B21: =IF(Allocation!F20="","",VLOOKUP(A21,Allocation!$A$2:$I$47,3)) -> Leah H | C21: =IF(B21="","",VLOOKUP(A21,Allocation!$A$2:$I$47,4,)) -> 73 | D21: =IF(B21="","",VLOOKUP(A21,Allocation!$A$2:$I$47,6,)) -> 2 | G21: Michael H | H21: =IF(G21="","",VLOOKUP(G21,$B$4:$C$48,2,)) -> 82 | L21: =H21 -> 82 | M21: =G21 -> Michael H | N21: Total Load | Q21: =SUM(Q19,T16,T5,650) -> 2195
A22: 19 | B22: =IF(Allocation!F21="","",VLOOKUP(A22,Allocation!$A$2:$I$47,3)) | C22: =IF(B22="","",VLOOKUP(A22,Allocation!$A$2:$I$47,4,)) | D22: =IF(B22="","",VLOOKUP(A22,Allocation!$A$2:$I$47,6,)) | G22: Kiran R | H22: =IF(G22="","",VLOOKUP(G22,$B$4:$C$48,2,)) -> 95 | L22: =H22 -> 95 | M22: =G22 -> Kiran R | N22: Total Load per Paddler | Q22: =SUM(Q19,T16,T5,650)/20 -> 109.75
A23: 20 | B23: =IF(Allocation!F22="","",VLOOKUP(A23,Allocation!$A$2:$I$47,3)) | C23: =IF(B23="","",VLOOKUP(A23,Allocation!$A$2:$I$47,4,)) | D23: =IF(B23="","",VLOOKUP(A23,Allocation!$A$2:$I$47,6,))
A24: 21 | B24: =IF(Allocation!F23="","",VLOOKUP(A24,Allocation!$A$2:$I$47,3)) -> Rohini | C24: =IF(B24="","",VLOOKUP(A24,Allocation!$A$2:$I$47,4,)) -> 70 | D24: =IF(B24="","",VLOOKUP(A24,Allocation!$A$2:$I$47,6,)) -> 3
A25: 22 | B25: =IF(Allocation!F24="","",VLOOKUP(A25,Allocation!$A$2:$I$47,3)) | C25: =IF(B25="","",VLOOKUP(A25,Allocation!$A$2:$I$47,4,)) | D25: =IF(B25="","",VLOOKUP(A25,Allocation!$A$2:$I$47,6,)) | F25: Heat 2
A26: 23 | B26: =IF(Allocation!F25="","",VLOOKUP(A26,Allocation!$A$2:$I$47,3)) -> Lianna C | C26: =IF(B26="","",VLOOKUP(A26,Allocation!$A$2:$I$47,4,)) -> 71 | D26: =IF(B26="","",VLOOKUP(A26,Allocation!$A$2:$I$47,6,)) -> 3 | G26: Helen F | H26: =IF(G26="","",VLOOKUP(G26,$B$4:$C$48,2,)) -> 55 | L26: Kg's | M26: Left | N26: Right | O26: Kg's | T26: =H26+14 -> 69 | U26: 6 | V26: =(U26)/6 -> 1 | W26: =V26*T26 -> 69
A27: 24 | B27: =IF(Allocation!F26="","",VLOOKUP(A27,Allocation!$A$2:$I$47,3)) -> Michael H | C27: =IF(B27="","",VLOOKUP(A27,Allocation!$A$2:$I$47,4,)) -> 82 | D27: =IF(B27="","",VLOOKUP(A27,Allocation!$A$2:$I$47,6,)) -> 2 | F27: =IF(G27="","",VLOOKUP(G27,$B$4:$C$48,2,)) -> 84 | G27: Diego E | H27: Lianna C | I27: =IF(H27="","",VLOOKUP(H27,$B$4:$C$48,2,)) -> 71 | K27: 1 | L27: =F27 -> 84 | M27: =G27 -> Diego E | N27: =H27 -> Lianna C | O27: =I27 -> 71 | P27: =O27-L27 -> -13 | Q27: 300 | R27: =Q27/350 -> 0.85714286 | S27: =P27*R27 -> -11.142857 | T27: =L27+O27 -> 155 | U27: 4.5 | V27: =(U27)/6 -> 0.75 | W27: =V27*T27 -> 116.25
A28: 25 | B28: =IF(Allocation!F27="","",VLOOKUP(A28,Allocation!$A$2:$I$47,3)) -> Andrew B | C28: =IF(B28="","",VLOOKUP(A28,Allocation!$A$2:$I$47,4,)) -> 75 | D28: =IF(B28="","",VLOOKUP(A28,Allocation!$A$2:$I$47,6,)) -> 3 | F28: =IF(G28="","",VLOOKUP(G28,$B$4:$C$48,2,)) -> 64 | G28: Deb H | H28: Amanda D | I28: =IF(H28="","",VLOOKUP(H28,$B$4:$C$48,2,)) -> 70 | K28: 2 | L28: =F28 -> 64 | M28: =G28 -> Deb H | N28: =H28 -> Amanda D | O28: =I28 -> 70 | P28: =O28-L28 -> 6 | Q28: 330 | R28: =Q28/350 -> 0.94285714 | S28: =P28*R28 -> 5.6571429 | T28: =L28+O28 -> 134 | U28: 3.5 | V28: =(U28)/6 -> 0.58333333 | W28: =V28*T28 -> 78.166667
A29: 26 | B29: =IF(Allocation!F28="","",VLOOKUP(A29,Allocation!$A$2:$I$47,3)) -> Diego E | C29: =IF(B29="","",VLOOKUP(A29,Allocation!$A$2:$I$47,4,)) -> 84 | D29: =IF(B29="","",VLOOKUP(A29,Allocation!$A$2:$I$47,6,)) -> 3 | F29: =IF(G29="","",VLOOKUP(G29,$B$4:$C$48,2,)) -> 65 | G29: Andrea M | H29: Victoria H | I29: =IF(H29="","",VLOOKUP(H29,$B$4:$C$48,2,)) -> 58 | K29: 3 | L29: =F29 -> 65 | M29: =G29 -> Andrea M | N29: =H29 -> Victoria H | O29: =I29 -> 58 | P29: =O29-L29 -> -7 | Q29: 350 | R29: =Q29/350 -> 1 | S29: =P29*R29 -> -7 | T29: =L29+O29 -> 123 | U29: 2.5 | V29: =(U29)/6 -> 0.41666667 | W29: =V29*T29 -> 51.25
A30: 27 | B30: =IF(Allocation!F29="","",VLOOKUP(A30,Allocation!$A$2:$I$47,3)) -> Simon F | C30: =IF(B30="","",VLOOKUP(A30,Allocation!$A$2:$I$47,4,)) -> 64 | D30: =IF(B30="","",VLOOKUP(A30,Allocation!$A$2:$I$47,6,)) -> 2 | F30: =IF(G30="","",VLOOKUP(G30,$B$4:$C$48,2,)) -> 91 | G30: Paul J | H30: Andrew B | I30: =IF(H30="","",VLOOKUP(H30,$B$4:$C$48,2,)) -> 75 | K30: 4 | L30: =F30 -> 91 | M30: =G30 -> Paul J | N30: =H30 -> Andrew B | O30: =I30 -> 75 | P30: =O30-L30 -> -16 | Q30: 350 | R30: =Q30/350 -> 1 | S30: =P30*R30 -> -16 | T30: =L30+O30 -> 166 | U30: 1.5 | V30: =(U30)/6 -> 0.25 | W30: =V30*T30 -> 41.5
A31: 28 | B31: =IF(Allocation!F30="","",VLOOKUP(A31,Allocation!$A$2:$I$47,3)) -> Andrew H | C31: =IF(B31="","",VLOOKUP(A31,Allocation!$A$2:$I$47,4,)) -> 77 | D31: =IF(B31="","",VLOOKUP(A31,Allocation!$A$2:$I$47,6,)) -> 2 | F31: =IF(G31="","",VLOOKUP(G31,$B$4:$C$48,2,)) -> 74 | G31: Alison M | H31: Rohini | I31: =IF(H31="","",VLOOKUP(H31,$B$4:$C$48,2,)) -> 70 | K31: 5 | L31: =F31 -> 74 | M31: =G31 -> Alison M | N31: =H31 -> Rohini | O31: =I31 -> 70 | P31: =O31-L31 -> -4 | Q31: 350 | R31: =Q31/350 -> 1 | S31: =P31*R31 -> -4 | T31: =L31+O31 -> 144 | U31: 0.5 | V31: =(U31)/6 -> 0.083333333 | W31: =V31*T31 -> 12
A32: 29 | B32: =IF(Allocation!F31="","",VLOOKUP(A32,Allocation!$A$2:$I$47,3)) -> Detlef H | C32: =IF(B32="","",VLOOKUP(A32,Allocation!$A$2:$I$47,4,)) -> 90 | D32: =IF(B32="","",VLOOKUP(A32,Allocation!$A$2:$I$47,6,)) -> 2 | F32: =IF(G32="","",VLOOKUP(G32,$B$4:$C$48,2,)) -> 77 | G32: Andrew H | H32: Kiran R | I32: =IF(H32="","",VLOOKUP(H32,$B$4:$C$48,2,)) -> 95 | K32: 6 | L32: =F32 -> 77 | M32: =G32 -> Andrew H | N32: =H32 -> Kiran R | O32: =I32 -> 95 | P32: =O32-L32 -> 18 | Q32: 350 | R32: =Q32/350 -> 1 | S32: =P32*R32 -> 18 | T32: =L32+O32 -> 172 | U32: -0.5 | V32: =(U32)/6 -> -0.083333333 | W32: =V32*T32 -> -14.333333
A33: 30 | B33: =IF(Allocation!F32="","",VLOOKUP(A33,Allocation!$A$2:$I$47,3)) -> Paul J | C33: =IF(B33="","",VLOOKUP(A33,Allocation!$A$2:$I$47,4,)) -> 91 | D33: =IF(B33="","",VLOOKUP(A33,Allocation!$A$2:$I$47,6,)) -> 3 | F33: =IF(G33="","",VLOOKUP(G33,$B$4:$C$48,2,)) -> 52 | G33: Miu | H33: Jocelyn K | I33: =IF(H33="","",VLOOKUP(H33,$B$4:$C$48,2,)) -> 58 | K33: 7 | L33: =F33 -> 52 | M33: =G33 -> Miu | N33: =H33 -> Jocelyn K | O33: =I33 -> 58 | P33: =O33-L33 -> 6 | Q33: 350 | R33: =Q33/350 -> 1 | S33: =P33*R33 -> 6 | T33: =L33+O33 -> 110 | U33: -1.5 | V33: =(U33)/6 -> -0.25 | W33: =V33*T33 -> -27.5
A34: 31 | B34: =IF(Allocation!F33="","",VLOOKUP(A34,Allocation!$A$2:$I$47,3)) -> Jaid | C34: =IF(B34="","",VLOOKUP(A34,Allocation!$A$2:$I$47,4,)) -> 68 | D34: =IF(B34="","",VLOOKUP(A34,Allocation!$A$2:$I$47,6,)) -> 3 | F34: =IF(G34="","",VLOOKUP(G34,$B$4:$C$48,2,)) -> 58 | G34: Alice C | H34: Jaid | I34: =IF(H34="","",VLOOKUP(H34,$B$4:$C$48,2,)) -> 68 | K34: 8 | L34: =F34 -> 58 | M34: =G34 -> Alice C | N34: =H34 -> Jaid | O34: =I34 -> 68 | P34: =O34-L34 -> 10 | Q34: 350 | R34: =Q34/350 -> 1 | S34: =P34*R34 -> 10 | T34: =L34+O34 -> 126 | U34: -2.5 | V34: =(U34)/6 -> -0.41666667 | W34: =V34*T34 -> -52.5
A35: 32 | B35: =IF(Allocation!F34="","",VLOOKUP(A35,Allocation!$A$2:$I$47,3)) -> Kiran R | C35: =IF(B35="","",VLOOKUP(A35,Allocation!$A$2:$I$47,4,)) -> 95 | D35: =IF(B35="","",VLOOKUP(A35,Allocation!$A$2:$I$47,6,)) -> 2 | F35: =IF(G35="","",VLOOKUP(G35,$B$4:$C$48,2,)) -> 82 | G35: Michael H | H35: Richard V | I35: =IF(H35="","",VLOOKUP(H35,$B$4:$C$48,2,)) -> 90 | K35: 9 | L35: =F35 -> 82 | M35: =G35 -> Michael H | N35: =H35 -> Richard V | O35: =I35 -> 90 | P35: =O35-L35 -> 8 | Q35: 330 | R35: =Q35/350 -> 0.94285714 | S35: =P35*R35 -> 7.5428571 | T35: =L35+O35 -> 172 | U35: -3.5 | V35: =(U35)/6 -> -0.58333333 | W35: =V35*T35 -> -100.33333
A36: 33 | B36: =IF(Allocation!F35="","",VLOOKUP(A36,Allocation!$A$2:$I$47,3)) -> Marc | C36: =IF(B36="","",VLOOKUP(A36,Allocation!$A$2:$I$47,4,)) -> 71 | D36: =IF(B36="","",VLOOKUP(A36,Allocation!$A$2:$I$47,6,)) -> 3 | F36: =IF(G36="","",VLOOKUP(G36,$B$4:$C$48,2,)) -> 74 | G36: Janet A | H36: Marc | I36: =IF(H36="","",VLOOKUP(H36,$B$4:$C$48,2,)) -> 71 | K36: 10 | L36: =F36 -> 74 | M36: =G36 -> Janet A | N36: =H36 -> Marc | O36: =I36 -> 71 | P36: =O36-L36 -> -3 | Q36: 300 | R36: =Q36/350 -> 0.85714286 | S36: =P36*R36 -> -2.5714286 | T36: =L36+O36 -> 145 | U36: -4.5 | V36: =(U36)/6 -> -0.75 | W36: =V36*T36 -> -108.75
A37: 34 | B37: =IF(Allocation!F36="","",VLOOKUP(A37,Allocation!$A$2:$I$47,3)) | C37: =IF(B37="","",VLOOKUP(A37,Allocation!$A$2:$I$47,4,)) | D37: =IF(B37="","",VLOOKUP(A37,Allocation!$A$2:$I$47,6,)) | G37: S-J | H37: =IF(G37="","",VLOOKUP(G37,$B$4:$C$48,2,)) -> 62 | L37: 3 | P37: =O37-L37 -> -3 | Q37: 420 | R37: =Q37/350 -> 1.2 | S37: =P37*R37 -> -3.6 | T37: =H37+7 -> 69 | U37: -6 | V37: =(U37)/6 -> -1 | W37: =V37*T37 -> -69
A38: 35 | B38: =IF(Allocation!F37="","",VLOOKUP(A38,Allocation!$A$2:$I$47,3)) -> Richard V | C38: =IF(B38="","",VLOOKUP(A38,Allocation!$A$2:$I$47,4,)) -> 90 | D38: =IF(B38="","",VLOOKUP(A38,Allocation!$A$2:$I$47,6,)) -> 2 | L38: =SUM(L27:L37) -> 724 | O38: =SUM(O27:O37) -> 726 | S38: =SUM(S27:S37) -> 2.8857143 | W38: =SUM(W26:W37) -> -4.25
A39: 36 | B39: =IF(Allocation!F38="","",VLOOKUP(A39,Allocation!$A$2:$I$47,3)) -> Andrea M | C39: =IF(B39="","",VLOOKUP(A39,Allocation!$A$2:$I$47,4,)) -> 65 | D39: =IF(B39="","",VLOOKUP(A39,Allocation!$A$2:$I$47,6,)) -> 3 | F39: Reserves: | L39: Res. | O39: 87 | S39: left-right | W39: back-front
A40: 37 | B40: =IF(Allocation!F39="","",VLOOKUP(A40,Allocation!$A$2:$I$47,3)) | C40: =IF(B40="","",VLOOKUP(A40,Allocation!$A$2:$I$47,4,)) | D40: =IF(B40="","",VLOOKUP(A40,Allocation!$A$2:$I$47,6,)) | G40: Leah H | H40: =IF(G40="","",VLOOKUP(G40,$B$4:$C$48,2,)) -> 73 | L40: =H40 -> 73 | M40: =G40 -> Leah H | N40: Total Paddlers Weight | Q40: =SUM(O27:O36,L27:L36) -> 1447 | S40: balance | W40: balance
A41: 38 | B41: =IF(Allocation!F40="","",VLOOKUP(A41,Allocation!$A$2:$I$47,3)) | C41: =IF(B41="","",VLOOKUP(A41,Allocation!$A$2:$I$47,4,)) | D41: =IF(B41="","",VLOOKUP(A41,Allocation!$A$2:$I$47,6,)) | G41: Divina | H41: =IF(G41="","",VLOOKUP(G41,$B$4:$C$48,2,)) -> 54 | L41: =H41 -> 54 | M41: =G41 -> Divina | N41: Average Paddler Weight | Q41: =SUM(O27:O36,L27:L36)/20 -> 72.35 | S41: Aim for weight under 5 kg | W41: Aim for range of - 15 kg to -25 kg
...

Sheet Master Mix
G2: Enter names into the blue zones only - match the names from the "Name" column
A3: No | B3: Name | C3: Weight | D3: Master Mix
A4: 1 | B4: =IF(Allocation!G3="","",VLOOKUP(A4,Allocation!$A$2:$I$47,3)) | C4: =IF(B4="","",VLOOKUP(A4,Allocation!$A$2:$I$47,4,)) | D4: =IF(B4="","",VLOOKUP(A4,Allocation!$A$2:$I$47,7,)) | F4: Heat 1
A5: 2 | B5: =IF(Allocation!G4="","",VLOOKUP(A5,Allocation!$A$2:$I$47,3)) | C5: =IF(B5="","",VLOOKUP(A5,Allocation!$A$2:$I$47,4,)) | D5: =IF(B5="","",VLOOKUP(A5,Allocation!$A$2:$I$47,7,)) | H5: =IF(G5="","",VLOOKUP(G5,$B$4:$C$48,2,)) | L5: Kg's | M5: Left | N5: Right | O5: Kg's | T5: =H5+14 -> #VALUE! | U5: 6 | V5: =(U5)/6 -> 1 | W5: =V5*T5 -> #VALUE!
A6: 3 | B6: =IF(Allocation!G5="","",VLOOKUP(A6,Allocation!$A$2:$I$47,3)) | C6: =IF(B6="","",VLOOKUP(A6,Allocation!$A$2:$I$47,4,)) | D6: =IF(B6="","",VLOOKUP(A6,Allocation!$A$2:$I$47,7,)) | F6: =IF(G6="","",VLOOKUP(G6,$B$4:$C$48,2,)) | I6: =IF(H6="","",VLOOKUP(H6,$B$4:$C$48,2,)) | K6: 1 | L6: =F6 | M6: =G6 -> 0 | N6: =H6 -> 0 | O6: =I6 | P6: =O6-L6 -> #VALUE! | Q6: 300 | R6: =Q6/350 -> 0.85714286 | S6: =P6*R6 -> #VALUE! | T6: =L6+O6 -> #VALUE! | U6: 4.5 | V6: =(U6)/6 -> 0.75 | W6: =V6*T6 -> #VALUE!
A7: 4 | B7: =IF(Allocation!G6="","",VLOOKUP(A7,Allocation!$A$2:$I$47,3)) | C7: =IF(B7="","",VLOOKUP(A7,Allocation!$A$2:$I$47,4,)) | D7: =IF(B7="","",VLOOKUP(A7,Allocation!$A$2:$I$47,7,)) | F7: =IF(G7="","",VLOOKUP(G7,$B$4:$C$48,2,)) | I7: =IF(H7="","",VLOOKUP(H7,$B$4:$C$29,2,)) | K7: 2 | L7: =F7 | M7: =G7 -> 0 | N7: =H7 -> 0 | O7: =I7 | P7: =O7-L7 -> #VALUE! | Q7: 330 | R7: =Q7/350 -> 0.94285714 | S7: =P7*R7 -> #VALUE! | T7: =L7+O7 -> #VALUE! | U7: 3.5 | V7: =(U7)/6 -> 0.58333333 | W7: =V7*T7 -> #VALUE!
A8: 5 | B8: =IF(Allocation!G7="","",VLOOKUP(A8,Allocation!$A$2:$I$47,3)) | C8: =IF(B8="","",VLOOKUP(A8,Allocation!$A$2:$I$47,4,)) | D8: =IF(B8="","",VLOOKUP(A8,Allocation!$A$2:$I$47,7,)) | F8: =IF(G8="","",VLOOKUP(G8,$B$4:$C$48,2,)) | I8: =IF(H8="","",VLOOKUP(H8,$B$4:$C$29,2,)) | K8: 3 | L8: =F8 | M8: =G8 -> 0 | N8: =H8 -> 0 | O8: =I8 | P8: =O8-L8 -> #VALUE! | Q8: 350 | R8: =Q8/350 -> 1 | S8: =P8*R8 -> #VALUE! | T8: =L8+O8 -> #VALUE! | U8: 2.5 | V8: =(U8)/6 -> 0.41666667 | W8: =V8*T8 -> #VALUE!
A9: 6 | B9: =IF(Allocation!G8="","",VLOOKUP(A9,Allocation!$A$2:$I$47,3)) | C9: =IF(B9="","",VLOOKUP(A9,Allocation!$A$2:$I$47,4,)) | D9: =IF(B9="","",VLOOKUP(A9,Allocation!$A$2:$I$47,7,)) | F9: =IF(G9="","",VLOOKUP(G9,$B$4:$C$48,2,)) | I9: =IF(H9="","",VLOOKUP(H9,$B$4:$C$29,2,)) | K9: 4 | L9: =F9 | M9: =G9 -> 0 | N9: =H9 -> 0 | O9: =I9 | P9: =O9-L9 -> #VALUE! | Q9: 350 | R9: =Q9/350 -> 1 | S9: =P9*R9 -> #VALUE! | T9: =L9+O9 -> #VALUE! | U9: 1.5 | V9: =(U9)/6 -> 0.25 | W9: =V9*T9 -> #VALUE!
A10: 7 | B10: =IF(Allocation!G9="","",VLOOKUP(A10,Allocation!$A$2:$I$47,3)) | C10: =IF(B10="","",VLOOKUP(A10,Allocation!$A$2:$I$47,4,)) | D10: =IF(B10="","",VLOOKUP(A10,Allocation!$A$2:$I$47,7,)) | F10: =IF(G10="","",VLOOKUP(G10,$B$4:$C$48,2,)) | I10: =IF(H10="","",VLOOKUP(H10,$B$4:$C$29,2,)) | K10: 5 | L10: =F10 | M10: =G10 -> 0 | N10: =H10 -> 0 | O10: =I10 | P10: =O10-L10 -> #VALUE! | Q10: 350 | R10: =Q10/350 -> 1 | S10: =P10*R10 -> #VALUE! | T10: =L10+O10 -> #VALUE! | U10: 0.5 | V10: =(U10)/6 -> 0.083333333 | W10: =V10*T10 -> #VALUE!
A11: 8 | B11: =IF(Allocation!G10="","",VLOOKUP(A11,Allocation!$A$2:$I$47,3)) | C11: =IF(B11="","",VLOOKUP(A11,Allocation!$A$2:$I$47,4,)) | D11: =IF(B11="","",VLOOKUP(A11,Allocation!$A$2:$I$47,7,)) | F11: =IF(G11="","",VLOOKUP(G11,$B$4:$C$48,2,)) | I11: =IF(H11="","",VLOOKUP(H11,$B$4:$C$29,2,)) | K11: 6 | L11: =F11 | M11: =G11 -> 0 | N11: =H11 -> 0 | O11: =I11 | P11: =O11-L11 -> #VALUE! | Q11: 350 | R11: =Q11/350 -> 1 | S11: =P11*R11 -> #VALUE! | T11: =L11+O11 -> #VALUE! | U11: -0.5 | V11: =(U11)/6 -> -0.083333333 | W11: =V11*T11 -> #VALUE!
A12: 9 | B12: =IF(Allocation!G11="","",VLOOKUP(A12,Allocation!$A$2:$I$47,3)) | C12: =IF(B12="","",VLOOKUP(A12,Allocation!$A$2:$I$47,4,)) | D12: =IF(B12="","",VLOOKUP(A12,Allocation!$A$2:$I$47,7,)) | F12: =IF(G12="","",VLOOKUP(G12,$B$4:$C$48,2,)) | I12: =IF(H12="","",VLOOKUP(H12,$B$4:$C$29,2,)) | K12: 7 | L12: =F12 | M12: =G12 -> 0 | N12: =H12 -> 0 | O12: =I12 | P12: =O12-L12 -> #VALUE! | Q12: 350 | R12: =Q12/350 -> 1 | S12: =P12*R12 -> #VALUE! | T12: =L12+O12 -> #VALUE! | U12: -1.5 | V12: =(U12)/6 -> -0.25 | W12: =V12*T12 -> #VALUE!
A13: 10 | B13: =IF(Allocation!G12="","",VLOOKUP(A13,Allocation!$A$2:$I$47,3)) | C13: =IF(B13="","",VLOOKUP(A13,Allocation!$A$2:$I$47,4,)) | D13: =IF(B13="","",VLOOKUP(A13,Allocation!$A$2:$I$47,7,)) | F13: =IF(G13="","",VLOOKUP(G13,$B$4:$C$48,2,)) | I13: =IF(H13="","",VLOOKUP(H13,$B$4:$C$29,2,)) | K13: 8 | L13: =F13 | M13: =G13 -> 0 | N13: =H13 -> 0 | O13: =I13 | P13: =O13-L13 -> #VALUE! | Q13: 350 | R13: =Q13/350 -> 1 | S13: =P13*R13 -> #VALUE! | T13: =L13+O13 -> #VALUE! | U13: -2.5 | V13: =(U13)/6 -> -0.41666667 | W13: =V13*T13 -> #VALUE!
A14: 11 | B14: =IF(Allocation!G13="","",VLOOKUP(A14,Allocation!$A$2:$I$47,3)) | C14: =IF(B14="","",VLOOKUP(A14,Allocation!$A$2:$I$47,4,)) | D14: =IF(B14="","",VLOOKUP(A14,Allocation!$A$2:$I$47,7,)) | F14: =IF(G14="","",VLOOKUP(G14,$B$4:$C$48,2,)) | I14: =IF(H14="","",VLOOKUP(H14,$B$4:$C$29,2,)) | K14: 9 | L14: =F14 | M14: =G14 -> 0 | N14: =H14 -> 0 | O14: =I14 | P14: =O14-L14 -> #VALUE! | Q14: 330 | R14: =Q14/350 -> 0.94285714 | S14: =P14*R14 -> #VALUE! | T14: =L14+O14 -> #VALUE! | U14: -3.5 | V14: =(U14)/6 -> -0.58333333 | W14: =V14*T14 -> #VALUE!
A15: 12 | B15: =IF(Allocation!G14="","",VLOOKUP(A15,Allocation!$A$2:$I$47,3)) | C15: =IF(B15="","",VLOOKUP(A15,Allocation!$A$2:$I$47,4,)) | D15: =IF(B15="","",VLOOKUP(A15,Allocation!$A$2:$I$47,7,)) | F15: =IF(G15="","",VLOOKUP(G15,$B$4:$C$48,2,)) | I15: =IF(H15="","",VLOOKUP(H15,$B$4:$C$29,2,)) | K15: 10 | L15: =F15 | M15: =G15 -> 0 | N15: =H15 -> 0 | O15: =I15 | P15: =O15-L15 -> #VALUE! | Q15: 300 | R15: =Q15/350 -> 0.85714286 | S15: =P15*R15 -> #VALUE! | T15: =L15+O15 -> #VALUE! | U15: -4.5 | V15: =(U15)/6 -> -0.75 | W15: =V15*T15 -> #VALUE!
A16: 13 | B16: =IF(Allocation!G15="","",VLOOKUP(A16,Allocation!$A$2:$I$47,3)) | C16: =IF(B16="","",VLOOKUP(A16,Allocation!$A$2:$I$47,4,)) | D16: =IF(B16="","",VLOOKUP(A16,Allocation!$A$2:$I$47,7,)) | H16: =IF(G16="","",VLOOKUP(G16,$B$4:$C$48,2,)) | L16: 3 | P16: =O16-L16 -> -3 | Q16: 420 | R16: =Q16/350 -> 1.2 | S16: =P16*R16 -> -3.6 | T16: =H16+7 -> #VALUE! | U16: -6 | V16: =(U16)/6 -> -1 | W16: =V16*T16 -> #VALUE!
A17: 14 | B17: =IF(Allocation!G16="","",VLOOKUP(A17,Allocation!$A$2:$I$47,3)) | C17: =IF(B17="","",VLOOKUP(A17,Allocation!$A$2:$I$47,4,)) | D17: =IF(B17="","",VLOOKUP(A17,Allocation!$A$2:$I$47,7,)) | L17: =SUM(L6:L16) -> 3 | O17: =SUM(O6:O16) -> 0 | S17: =SUM(S6:S16) -> #VALUE! | W17: =SUM(W5:W16) -> #VALUE!
A18: 15 | B18: =IF(Allocation!G17="","",VLOOKUP(A18,Allocation!$A$2:$I$47,3)) | C18: =IF(B18="","",VLOOKUP(A18,Allocation!$A$2:$I$47,4,)) | D18: =IF(B18="","",VLOOKUP(A18,Allocation!$A$2:$I$47,7,)) | F18: Reserves: | L18: Res. | O18: 87 | S18: left-right | W18: back-front
A19: 16 | B19: =IF(Allocation!G18="","",VLOOKUP(A19,Allocation!$A$2:$I$47,3)) | C19: =IF(B19="","",VLOOKUP(A19,Allocation!$A$2:$I$47,4,)) | D19: =IF(B19="","",VLOOKUP(A19,Allocation!$A$2:$I$47,7,)) | H19: =IF(G19="","",VLOOKUP(G19,$B$4:$C$29,2,)) | L19: =H19 | M19: =G19 -> 0 | N19: Total Paddlers Weight | Q19: =SUM(O6:O15,L6:L15) -> 0 | S19: balance | W19: balance
A20: 17 | B20: =IF(Allocation!G19="","",VLOOKUP(A20,Allocation!$A$2:$I$47,3)) | C20: =IF(B20="","",VLOOKUP(A20,Allocation!$A$2:$I$47,4,)) | D20: =IF(B20="","",VLOOKUP(A20,Allocation!$A$2:$I$47,7,)) | H20: =IF(G20="","",VLOOKUP(G20,$B$4:$C$29,2,)) | L20: =H20 | M20: =G20 -> 0 | N20: Average Paddler Weight | Q20: =SUM(O6:O15,L6:L15)/20 -> 0 | S20: Aim for weight under 5 kg | W20: Aim for range of - 15 kg to -25 kg
A21: 18 | B21: =IF(Allocation!G20="","",VLOOKUP(A21,Allocation!$A$2:$I$47,3)) | C21: =IF(B21="","",VLOOKUP(A21,Allocation!$A$2:$I$47,4,)) | D21: =IF(B21="","",VLOOKUP(A21,Allocation!$A$2:$I$47,7,)) | H21: =IF(G21="","",VLOOKUP(G21,$B$4:$C$29,2,)) | L21: =H21 | M21: =G21 -> 0 | N21: Total Load | Q21: =SUM(Q19,T16,T5,650) -> #VALUE!
A22: 19 | B22: =IF(Allocation!G21="","",VLOOKUP(A22,Allocation!$A$2:$I$47,3)) | C22: =IF(B22="","",VLOOKUP(A22,Allocation!$A$2:$I$47,4,)) | D22: =IF(B22="","",VLOOKUP(A22,Allocation!$A$2:$I$47,7,)) | H22: =IF(G22="","",VLOOKUP(G22,$B$4:$C$29,2,)) | L22: =H22 | M22: =G22 -> 0 | N22: Total Load per Paddler | Q22: =SUM(Q19,T16,T5,650)/20 -> #VALUE!
A23: 20 | B23: =IF(Allocation!G22="","",VLOOKUP(A23,Allocation!$A$2:$I$47,3)) | C23: =IF(B23="","",VLOOKUP(A23,Allocation!$A$2:$I$47,4,)) | D23: =IF(B23="","",VLOOKUP(A23,Allocation!$A$2:$I$47,7,))
A24: 21 | B24: =IF(Allocation!G23="","",VLOOKUP(A24,Allocation!$A$2:$I$47,3)) | C24: =IF(B24="","",VLOOKUP(A24,Allocation!$A$2:$I$47,4,)) | D24: =IF(B24="","",VLOOKUP(A24,Allocation!$A$2:$I$47,7,))
A25: 22 | B25: =IF(Allocation!G24="","",VLOOKUP(A25,Allocation!$A$2:$I$47,3)) | C25: =IF(B25="","",VLOOKUP(A25,Allocation!$A$2:$I$47,4,)) | D25: =IF(B25="","",VLOOKUP(A25,Allocation!$A$2:$I$47,7,)) | F25: Heat 2
A26: 23 | B26: =IF(Allocation!G25="","",VLOOKUP(A26,Allocation!$A$2:$I$47,3)) | C26: =IF(B26="","",VLOOKUP(A26,Allocation!$A$2:$I$47,4,)) | D26: =IF(B26="","",VLOOKUP(A26,Allocation!$A$2:$I$47,7,)) | H26: =IF(G26="","",VLOOKUP(G26,$B$4:$C$48,2,)) | L26: Kg's | M26: Left | N26: Right | O26: Kg's | T26: =H26+14 -> #VALUE! | U26: 6 | V26: =(U26)/6 -> 1 | W26: =V26*T26 -> #VALUE!
A27: 24 | B27: =IF(Allocation!G26="","",VLOOKUP(A27,Allocation!$A$2:$I$47,3)) | C27: =IF(B27="","",VLOOKUP(A27,Allocation!$A$2:$I$47,4,)) | D27: =IF(B27="","",VLOOKUP(A27,Allocation!$A$2:$I$47,7,)) | F27: =IF(G27="","",VLOOKUP(G27,$B$4:$C$48,2,)) | I27: =IF(H27="","",VLOOKUP(H27,$B$4:$C$48,2,)) | K27: 1 | L27: =F27 | M27: =G27 -> 0 | N27: =H27 -> 0 | O27: =I27 | P27: =O27-L27 -> #VALUE! | Q27: 300 | R27: =Q27/350 -> 0.85714286 | S27: =P27*R27 -> #VALUE! | T27: =L27+O27 -> #VALUE! | U27: 4.5 | V27: =(U27)/6 -> 0.75 | W27: =V27*T27 -> #VALUE!
A28: 25 | B28: =IF(Allocation!G27="","",VLOOKUP(A28,Allocation!$A$2:$I$47,3)) | C28: =IF(B28="","",VLOOKUP(A28,Allocation!$A$2:$I$47,4,)) | D28: =IF(B28="","",VLOOKUP(A28,Allocation!$A$2:$I$47,7,)) | F28: =IF(G28="","",VLOOKUP(G28,$B$4:$C$48,2,)) | I28: =IF(H28="","",VLOOKUP(H28,$B$4:$C$29,2,)) | K28: 2 | L28: =F28 | M28: =G28 -> 0 | N28: =H28 -> 0 | O28: =I28 | P28: =O28-L28 -> #VALUE! | Q28: 330 | R28: =Q28/350 -> 0.94285714 | S28: =P28*R28 -> #VALUE! | T28: =L28+O28 -> #VALUE! | U28: 3.5 | V28: =(U28)/6 -> 0.58333333 | W28: =V28*T28 -> #VALUE!
A29: 26 | B29: =IF(Allocation!G28="","",VLOOKUP(A29,Allocation!$A$2:$I$47,3)) | C29: =IF(B29="","",VLOOKUP(A29,Allocation!$A$2:$I$47,4,)) | D29: =IF(B29="","",VLOOKUP(A29,Allocation!$A$2:$I$47,7,)) | F29: =IF(G29="","",VLOOKUP(G29,$B$4:$C$48,2,)) | I29: =IF(H29="","",VLOOKUP(H29,$B$4:$C$29,2,)) | K29: 3 | L29: =F29 | M29: =G29 -> 0 | N29: =H29 -> 0 | O29: =I29 | P29: =O29-L29 -> #VALUE! | Q29: 350 | R29: =Q29/350 -> 1 | S29: =P29*R29 -> #VALUE! | T29: =L29+O29 -> #VALUE! | U29: 2.5 | V29: =(U29)/6 -> 0.41666667 | W29: =V29*T29 -> #VALUE!
A30: 27 | B30: =IF(Allocation!G29="","",VLOOKUP(A30,Allocation!$A$2:$I$47,3)) | C30: =IF(B30="","",VLOOKUP(A30,Allocation!$A$2:$I$47,4,)) | D30: =IF(B30="","",VLOOKUP(A30,Allocation!$A$2:$I$47,7,)) | F30: =IF(G30="","",VLOOKUP(G30,$B$4:$C$48,2,)) | I30: =IF(H30="","",VLOOKUP(H30,$B$4:$C$29,2,)) | K30: 4 | L30: =F30 | M30: =G30 -> 0 | N30: =H30 -> 0 | O30: =I30 | P30: =O30-L30 -> #VALUE! | Q30: 350 | R30: =Q30/350 -> 1 | S30: =P30*R30 -> #VALUE! | T30: =L30+O30 -> #VALUE! | U30: 1.5 | V30: =(U30)/6 -> 0.25 | W30: =V30*T30 -> #VALUE!
A31: 28 | B31: =IF(Allocation!G30="","",VLOOKUP(A31,Allocation!$A$2:$I$47,3)) | C31: =IF(B31="","",VLOOKUP(A31,Allocation!$A$2:$I$47,4,)) | D31: =IF(B31="","",VLOOKUP(A31,Allocation!$A$2:$I$47,7,)) | F31: =IF(G31="","",VLOOKUP(G31,$B$4:$C$48,2,)) | I31: =IF(H31="","",VLOOKUP(H31,$B$4:$C$29,2,)) | K31: 5 | L31: =F31 | M31: =G31 -> 0 | N31: =H31 -> 0 | O31: =I31 | P31: =O31-L31 -> #VALUE! | Q31: 350 | R31: =Q31/350 -> 1 | S31: =P31*R31 -> #VALUE! | T31: =L31+O31 -> #VALUE! | U31: 0.5 | V31: =(U31)/6 -> 0.083333333 | W31: =V31*T31 -> #VALUE!
A32: 29 | B32: =IF(Allocation!G31="","",VLOOKUP(A32,Allocation!$A$2:$I$47,3)) | C32: =IF(B32="","",VLOOKUP(A32,Allocation!$A$2:$I$47,4,)) | D32: =IF(B32="","",VLOOKUP(A32,Allocation!$A$2:$I$47,7,)) | F32: =IF(G32="","",VLOOKUP(G32,$B$4:$C$48,2,)) | I32: =IF(H32="","",VLOOKUP(H32,$B$4:$C$29,2,)) | K32: 6 | L32: =F32 | M32: =G32 -> 0 | N32: =H32 -> 0 | O32: =I32 | P32: =O32-L32 -> #VALUE! | Q32: 350 | R32: =Q32/350 -> 1 | S32: =P32*R32 -> #VALUE! | T32: =L32+O32 -> #VALUE! | U32: -0.5 | V32: =(U32)/6 -> -0.083333333 | W32: =V32*T32 -> #VALUE!
A33: 30 | B33: =IF(Allocation!G32="","",VLOOKUP(A33,Allocation!$A$2:$I$47,3)) | C33: =IF(B33="","",VLOOKUP(A33,Allocation!$A$2:$I$47,4,)) | D33: =IF(B33="","",VLOOKUP(A33,Allocation!$A$2:$I$47,7,)) | F33: =IF(G33="","",VLOOKUP(G33,$B$4:$C$48,2,)) | I33: =IF(H33="","",VLOOKUP(H33,$B$4:$C$29,2,)) | K33: 7 | L33: =F33 | M33: =G33 -> 0 | N33: =H33 -> 0 | O33: =I33 | P33: =O33-L33 -> #VALUE! | Q33: 350 | R33: =Q33/350 -> 1 | S33: =P33*R33 -> #VALUE! | T33: =L33+O33 -> #VALUE! | U33: -1.5 | V33: =(U33)/6 -> -0.25 | W33: =V33*T33 -> #VALUE!
A34: 31 | B34: =IF(Allocation!G33="","",VLOOKUP(A34,Allocation!$A$2:$I$47,3)) | C34: =IF(B34="","",VLOOKUP(A34,Allocation!$A$2:$I$47,4,)) | D34: =IF(B34="","",VLOOKUP(A34,Allocation!$A$2:$I$47,7,)) | F34: =IF(G34="","",VLOOKUP(G34,$B$4:$C$48,2,)) | I34: =IF(H34="","",VLOOKUP(H34,$B$4:$C$29,2,)) | K34: 8 | L34: =F34 | M34: =G34 -> 0 | N34: =H34 -> 0 | O34: =I34 | P34: =O34-L34 -> #VALUE! | Q34: 350 | R34: =Q34/350 -> 1 | S34: =P34*R34 -> #VALUE! | T34: =L34+O34 -> #VALUE! | U34: -2.5 | V34: =(U34)/6 -> -0.41666667 | W34: =V34*T34 -> #VALUE!
A35: 32 | B35: =IF(Allocation!G34="","",VLOOKUP(A35,Allocation!$A$2:$I$47,3)) | C35: =IF(B35="","",VLOOKUP(A35,Allocation!$A$2:$I$47,4,)) | D35: =IF(B35="","",VLOOKUP(A35,Allocation!$A$2:$I$47,7,)) | F35: =IF(G35="","",VLOOKUP(G35,$B$4:$C$48,2,)) | I35: =IF(H35="","",VLOOKUP(H35,$B$4:$C$29,2,)) | K35: 9 | L35: =F35 | M35: =G35 -> 0 | N35: =H35 -> 0 | O35: =I35 | P35: =O35-L35 -> #VALUE! | Q35: 330 | R35: =Q35/350 -> 0.94285714 | S35: =P35*R35 -> #VALUE! | T35: =L35+O35 -> #VALUE! | U35: -3.5 | V35: =(U35)/6 -> -0.58333333 | W35: =V35*T35 -> #VALUE!
A36: 33 | B36: =IF(Allocation!G35="","",VLOOKUP(A36,Allocation!$A$2:$I$47,3)) | C36: =IF(B36="","",VLOOKUP(A36,Allocation!$A$2:$I$47,4,)) | D36: =IF(B36="","",VLOOKUP(A36,Allocation!$A$2:$I$47,7,)) | F36: =IF(G36="","",VLOOKUP(G36,$B$4:$C$48,2,)) | I36: =IF(H36="","",VLOOKUP(H36,$B$4:$C$29,2,)) | K36: 10 | L36: =F36 | M36: =G36 -> 0 | N36: =H36 -> 0 | O36: =I36 | P36: =O36-L36 -> #VALUE! | Q36: 300 | R36: =Q36/350 -> 0.85714286 | S36: =P36*R36 -> #VALUE! | T36: =L36+O36 -> #VALUE! | U36: -4.5 | V36: =(U36)/6 -> -0.75 | W36: =V36*T36 -> #VALUE!
A37: 34 | B37: =IF(Allocation!G36="","",VLOOKUP(A37,Allocation!$A$2:$I$47,3)) | C37: =IF(B37="","",VLOOKUP(A37,Allocation!$A$2:$I$47,4,)) | D37: =IF(B37="","",VLOOKUP(A37,Allocation!$A$2:$I$47,7,)) | H37: =IF(G37="","",VLOOKUP(G37,$B$4:$C$48,2,)) | L37: 3 | P37: =O37-L37 -> -3 | Q37: 420 | R37: =Q37/350 -> 1.2 | S37: =P37*R37 -> -3.6 | T37: =H37+7 -> #VALUE! | U37: -6 | V37: =(U37)/6 -> -1 | W37: =V37*T37 -> #VALUE!
A38: 35 | B38: =IF(Allocation!G37="","",VLOOKUP(A38,Allocation!$A$2:$I$47,3)) | C38: =IF(B38="","",VLOOKUP(A38,Allocation!$A$2:$I$47,4,)) | D38: =IF(B38="","",VLOOKUP(A38,Allocation!$A$2:$I$47,7,)) | L38: =SUM(L27:L37) -> 3 | O38: =SUM(O27:O37) -> 0 | S38: =SUM(S27:S37) -> #VALUE! | W38: =SUM(W26:W37) -> #VALUE!
A39: 36 | B39: =IF(Allocation!G38="","",VLOOKUP(A39,Allocation!$A$2:$I$47,3)) | C39: =IF(B39="","",VLOOKUP(A39,Allocation!$A$2:$I$47,4,)) | D39: =IF(B39="","",VLOOKUP(A39,Allocation!$A$2:$I$47,7,)) | F39: Reserves: | L39: Res. | O39: 87 | S39: left-right | W39: back-front
A40: 37 | B40: =IF(Allocation!G39="","",VLOOKUP(A40,Allocation!$A$2:$I$47,3)) | C40: =IF(B40="","",VLOOKUP(A40,Allocation!$A$2:$I$47,4,)) | D40: =IF(B40="","",VLOOKUP(A40,Allocation!$A$2:$I$47,7,)) | H40: =IF(G40="","",VLOOKUP(G40,$B$4:$C$29,2,)) | L40: =H40 | M40: =G40 -> 0 | N40: Total Paddlers Weight | Q40: =SUM(O27:O36,L27:L36) -> 0 | S40: balance | W40: balance
A41: 38 | B41: =IF(Allocation!G40="","",VLOOKUP(A41,Allocation!$A$2:$I$47,3)) | C41: =IF(B41="","",VLOOKUP(A41,Allocation!$A$2:$I$47,4,)) | D41: =IF(B41="","",VLOOKUP(A41,Allocation!$A$2:$I$47,7,)) | H41: =IF(G41="","",VLOOKUP(G41,$B$4:$C$29,2,)) | L41: =H41 | M41: =G41 -> 0 | N41: Average Paddler Weight | Q41: =SUM(O27:O36,L27:L36)/20 -> 0 | S41: Aim for weight under 5 kg | W41: Aim for range of - 15 kg to -25 kg
...

Sheet Prem Open
G2: Enter names into the blue zones only - match the names from the "Name" column
A3: No | B3: Name | C3: Weight | D3: Prem Open
A4: 1 | B4: =IF(Allocation!H3="","",VLOOKUP(A4,Allocation!$A$2:$I$47,3)) -> Mary-Alice | C4: =IF(B4="","",VLOOKUP(A4,Allocation!$A$2:$I$47,4,)) -> 70 | D4: =IF(B4="","",VLOOKUP(A4,Allocation!$A$2:$I$47,8,)) -> 3 | F4: Heat 1
A5: 2 | B5: =IF(Allocation!H4="","",VLOOKUP(A5,Allocation!$A$2:$I$47,3)) -> Amanda D | C5: =IF(B5="","",VLOOKUP(A5,Allocation!$A$2:$I$47,4,)) -> 70 | D5: =IF(B5="","",VLOOKUP(A5,Allocation!$A$2:$I$47,8,)) -> 0 | G5: Sue T | H5: =IF(G5="","",VLOOKUP(G5,$B$4:$C$48,2,)) -> 63 | L5: Kg's | M5: Left | N5: Right | O5: Kg's | T5: =H5+14 -> 77 | U5: 6 | V5: =(U5)/6 -> 1 | W5: =V5*T5 -> 77
A6: 3 | B6: =IF(Allocation!H5="","",VLOOKUP(A6,Allocation!$A$2:$I$47,3)) -> Amanda F | C6: =IF(B6="","",VLOOKUP(A6,Allocation!$A$2:$I$47,4,)) -> 75 | D6: =IF(B6="","",VLOOKUP(A6,Allocation!$A$2:$I$47,8,)) -> 3 | F6: =IF(G6="","",VLOOKUP(G6,$B$4:$C$48,2,)) -> 84 | G6: Diego E | H6: Andrew B | I6: =IF(H6="","",VLOOKUP(H6,$B$4:$C$48,2,)) -> 75 | K6: 1 | L6: =F6 -> 84 | M6: =G6 -> Diego E | N6: =H6 -> Andrew B | O6: =I6 -> 75 | P6: =O6-L6 -> -9 | Q6: 300 | R6: =Q6/350 -> 0.85714286 | S6: =P6*R6 -> -7.7142857 | T6: =L6+O6 -> 159 | U6: 4.5 | V6: =(U6)/6 -> 0.75 | W6: =V6*T6 -> 119.25
A7: 4 | B7: =IF(Allocation!H6="","",VLOOKUP(A7,Allocation!$A$2:$I$47,3)) | C7: =IF(B7="","",VLOOKUP(A7,Allocation!$A$2:$I$47,4,)) | D7: =IF(B7="","",VLOOKUP(A7,Allocation!$A$2:$I$47,8,)) | F7: =IF(G7="","",VLOOKUP(G7,$B$4:$C$48,2,)) -> 91 | G7: Paul J | H7: Andrea M | I7: =IF(H7="","",VLOOKUP(H7,$B$4:$C$48,2,)) -> 65 | K7: 2 | L7: =F7 -> 91 | M7: =G7 -> Paul J | N7: =H7 -> Andrea M | O7: =I7 -> 65 | P7: =O7-L7 -> -26 | Q7: 330 | R7: =Q7/350 -> 0.94285714 | S7: =P7*R7 -> -24.514286 | T7: =L7+O7 -> 156 | U7: 3.5 | V7: =(U7)/6 -> 0.58333333 | W7: =V7*T7 -> 91
A8: 5 | B8: =IF(Allocation!H7="","",VLOOKUP(A8,Allocation!$A$2:$I$47,3)) | C8: =IF(B8="","",VLOOKUP(A8,Allocation!$A$2:$I$47,4,)) | D8: =IF(B8="","",VLOOKUP(A8,Allocation!$A$2:$I$47,8,)) | F8: =IF(G8="","",VLOOKUP(G8,$B$4:$C$48,2,)) -> 75 | G8: Amanda F | H8: Andrew H | I8: =IF(H8="","",VLOOKUP(H8,$B$4:$C$48,2,)) -> 77 | K8: 3 | L8: =F8 -> 75 | M8: =G8 -> Amanda F | N8: =H8 -> Andrew H | O8: =I8 -> 77 | P8: =O8-L8 -> 2 | Q8: 350 | R8: =Q8/350 -> 1 | S8: =P8*R8 -> 2 | T8: =L8+O8 -> 152 | U8: 2.5 | V8: =(U8)/6 -> 0.41666667 | W8: =V8*T8 -> 63.333333
A9: 6 | B9: =IF(Allocation!H8="","",VLOOKUP(A9,Allocation!$A$2:$I$47,3)) -> Bibiana A | C9: =IF(B9="","",VLOOKUP(A9,Allocation!$A$2:$I$47,4,)) -> 75 | D9: =IF(B9="","",VLOOKUP(A9,Allocation!$A$2:$I$47,8,)) -> 3 | F9: =IF(G9="","",VLOOKUP(G9,$B$4:$C$48,2,)) -> 95 | G9: Kiran R | H9: Detlef H | I9: =IF(H9="","",VLOOKUP(H9,$B$4:$C$48,2,)) -> 90 | K9: 4 | L9: =F9 -> 95 | M9: =G9 -> Kiran R | N9: =H9 -> Detlef H | O9: =I9 -> 90 | P9: =O9-L9 -> -5 | Q9: 350 | R9: =Q9/350 -> 1 | S9: =P9*R9 -> -5 | T9: =L9+O9 -> 185 | U9: 1.5 | V9: =(U9)/6 -> 0.25 | W9: =V9*T9 -> 46.25
A10: 7 | B10: =IF(Allocation!H9="","",VLOOKUP(A10,Allocation!$A$2:$I$47,3)) -> Deb H | C10: =IF(B10="","",VLOOKUP(A10,Allocation!$A$2:$I$47,4,)) -> 64 | D10: =IF(B10="","",VLOOKUP(A10,Allocation!$A$2:$I$47,8,)) -> 0 | F10: =IF(G10="","",VLOOKUP(G10,$B$4:$C$48,2,)) -> 67 | G10: Anne-Marie | H10: Mary-Alice | I10: =IF(H10="","",VLOOKUP(H10,$B$4:$C$48,2,)) -> 70 | K10: 5 | L10: =F10 -> 67 | M10: =G10 -> Anne-Marie | N10: =H10 -> Mary-Alice | O10: =I10 -> 70 | P10: =O10-L10 -> 3 | Q10: 350 | R10: =Q10/350 -> 1 | S10: =P10*R10 -> 3 | T10: =L10+O10 -> 137 | U10: 0.5 | V10: =(U10)/6 -> 0.083333333 | W10: =V10*T10 -> 11.416667
A11: 8 | B11: =IF(Allocation!H10="","",VLOOKUP(A11,Allocation!$A$2:$I$47,3)) -> Amy | C11: =IF(B11="","",VLOOKUP(A11,Allocation!$A$2:$I$47,4,)) -> 65 | D11: =IF(B11="","",VLOOKUP(A11,Allocation!$A$2:$I$47,8,)) -> 3 | F11: =IF(G11="","",VLOOKUP(G11,$B$4:$C$48,2,)) -> 68 | G11: Jaid | H11: Rachael H | I11: =IF(H11="","",VLOOKUP(H11,$B$4:$C$48,2,)) -> 85 | K11: 6 | L11: =F11 -> 68 | M11: =G11 -> Jaid | N11: =H11 -> Rachael H | O11: =I11 -> 85 | P11: =O11-L11 -> 17 | Q11: 350 | R11: =Q11/350 -> 1 | S11: =P11*R11 -> 17 | T11: =L11+O11 -> 153 | U11: -0.5 | V11: =(U11)/6 -> -0.083333333 | W11: =V11*T11 -> -12.75
A12: 9 | B12: =IF(Allocation!H11="","",VLOOKUP(A12,Allocation!$A$2:$I$47,3)) -> Jocelyn K | C12: =IF(B12="","",VLOOKUP(A12,Allocation!$A$2:$I$47,4,)) -> 58 | D12: =IF(B12="","",VLOOKUP(A12,Allocation!$A$2:$I$47,8,)) -> 0 | F12: =IF(G12="","",VLOOKUP(G12,$B$4:$C$48,2,)) -> 47 | G12: Alice S | H12: Liz Mc | I12: =IF(H12="","",VLOOKUP(H12,$B$4:$C$48,2,)) -> 64 | K12: 7 | L12: =F12 -> 47 | M12: =G12 -> Alice S | N12: =H12 -> Liz Mc | O12: =I12 -> 64 | P12: =O12-L12 -> 17 | Q12: 350 | R12: =Q12/350 -> 1 | S12: =P12*R12 -> 17 | T12: =L12+O12 -> 111 | U12: -1.5 | V12: =(U12)/6 -> -0.25 | W12: =V12*T12 -> -27.75
